Workbook

Sheet 汇总情况
A1: 融券互换测算
C2: 比例 | D2: (√)不包含SPV融ETF 判定为已对冲情形 | E2: 备注
A3: 1.互换名义本金（亿元） | D3: =SUM(D4) -> 20
A4: 其中： | B4: 融券互换 | D4: 20
A5: 2.净出资（亿元） | D5: =D6-D8 -> 9
A6: 出资规模： | D6: =D7 -> 14
A7: 其中： | B7: SPV申购 | C7: 0.7 | D7: =D4*C7 -> 14 | E7: 按名本的70%出资估计
A8: 回款规模： | D8: =SUM(D9) -> 5
A9: 其中： | B9: 互换预付金（按25%估计） | C9: 0.25 | D9: =D4*C9 -> 5
A11: 指标方面： | B11: 变化幅度 | D11: 业务开展后值
A12: 1.净资本/风险资本准备（风险覆盖率） 影响 | B12: ='1.2净资本(不含ETF空头)'!$H$32 -> -0.060150376 | D12: ='1.2净资本(不含ETF空头)'!$H$31 -> 1.6760841 | E12: 需>160%
A13: 2.流动性覆盖率(LCR) 影响 | B13: ='1.4LCR(不含ETF空头)'!$D$75 -> -0.12030394 | D13: ='1.4LCR(不含ETF空头)'!$D$74 -> 1.3102255 | E13: 需≥120%
A14: 3.净稳定资金率(NSFR) 影响 | B14: ='1.1NSFR(不含ETF空头)'!$D$78 -> -0.061567811 | D14: ='1.1NSFR(不含ETF空头)'!$D$77 -> 1.3237947 | E14: 需≥120%

Sheet 1.1NSFR(不含ETF空头)
A1: 证券公司净稳定资金率计算表
E2: 单位： | F2: 亿元
A3: 项目 | C3: 行次 | D3: 期末金额 | E3: 折算率 | F3: 折算后金额 | G3: 原始值
A4: 可用稳定资金 | C4: 1 | D4: =SUM(F5,F7:F12)+G4 -> 305.32 | G4: 305.32
A5: 其中： | B5: 1. 净资产 | C5: 2 | E5: 1 | F5: =D5*E5 -> 0 | G5: 不涉及净资本
B6: 2. 剩余存续期大于等于 1 年的借款和负债 | C6: 3
B7: 次级债务 | C7: 4 | E7: 1 | F7: =D7*E7 -> 0
B8: 长期借款 | C8: 5 | E8: 1 | F8: =D8*E8 -> 0 | G8: 监管回复互换预付金不能填入此列
B9: 应付债券 | C9: 6 | E9: 1 | F9: =D9*E9 -> 0
B10: 其他 | C10: 7 | E10: 1 | F10: =D10*E10 -> 0
B11: 3. 所有其他负债和权益 | C11: 8 | D11: =汇总情况!$D$9 -> 5 | E11: 0 | F11: =D11*E11 -> 0 | G11: 互换收到的预付金
B12: 4. 经中国证监会认可的调整项目 | C12: 9 | E12: 1 | F12: =D12*E12 -> 0
A13: 所需稳定资金 | C13: 10 | D13: =SUM(F15:F20,F22:F29,F31:F38,F40:F44,F47:F48,F50:F53,F55:F57,F59:F63,F66:F70,F72:F76)+G13 -> 230.64 | G13: 216.44
A14: 其中： | B14: 1. 高流动性资产 | C14: 11
B15: 货币资金 | C15: 12 | D15: =-汇总情况!$D$5 -> -9 | E15: 0 | F15: =D15*E15 -> 0
B16: 结算备付金 | C16: 13 | E16: 0 | F16: =D16*E16 -> 0
B17: 拆出资金（不足 1 年） | C17: 14 | E17: 0 | F17: =D17*E17 -> 0
B18: 存出保证金 | C18: 15 | E18: 0 | F18: =D18*E18 -> 0
B19: 买入返售金融资产 | C19: 16 | E19: 0 | F19: =D19*E19 -> 0
B20: 货币基金 | C20: 17 | E20: 0 | F20: =D20*E20 -> 0
B21: 2. 剩余存续期不足 1 年的证券 | C21: 18
B22: 国债、中央银行票据、国开债 | C22: 19 | E22: 0 | F22: =D22*E22 -> 0
B23: 政策性金融债、政府支持机构债券 | C23: 20 | E23: 0 | F23: =D23*E23 -> 0
B24: 地方政府债券 | C24: 21 | E24: 0 | F24: =D24*E24 -> 0
B25: 同业存单 | C25: 22 | E25: 0 | F25: =D25*E25 -> 0
B26: 信用评级 AAA 级的信用债券 | C26: 23 | E26: 0 | F26: =D26*E26 -> 0
B27: 信用评级 AAA 级以下，AA 级(不含）以上的信用债券 | C27: 24 | E27: 0.01 | F27: =D27*E27 -> 0
B28: 信用评级 AA 级以下，BBB 级(不含）以上的信用债券 | C28: 25 | E28: 0.03 | F28: =D28*E28 -> 0
B29: 信用评级 BBB 级以下的信用债券 | C29: 26 | E29: 0.05 | F29: =D29*E29 -> 0
B30: 3. 剩余存续期大于等于 1 年证券 | C30: 27
B31: 国债、中央银行票据、国开债 | C31: 28 | E31: 0.02 | F31: =D31*E31 -> 0
B32: 政策性金融债券、政府支持机构债券 | C32: 29 | E32: 0.02 | F32: =D32*E32 -> 0
B33: 地方政府债券 | C33: 30 | E33: 0.05 | F33: =D33*E33 -> 0
B34: 同业存单 | C34: 31 | E34: 0.05 | F34: =D34*E34 -> 0
B35: 信用评级 AAA 级的信用债券 | C35: 32 | E35: 0.1 | F35: =D35*E35 -> 0
B36: 信用评级 AAA 级以下，AA 级(不含）以上的信用债券 | C36: 33 | E36: 0.2 | F36: =D36*E36 -> 0
B37: 信用评级 AA 级以下，BBB 级(不含）以上的信用债券 | C37: 34 | E37: 0.3 | F37: =D37*E37 -> 0
B38: 信用评级 BBB 级以下的信用债券 | C38: 35 | E38: 0.5 | F38: =D38*E38 -> 0
B39: 4. 股票 | C39: 36
B40: 上海 180 指数、深圳 100 指数、沪深 300指数成分股 | C40: 37 | E40: 0.3 | F40: =D40*E40 -> 0 | G40: 对冲不需归0，正常填，区别于LCR
...

Sheet 1.2净资本(不含ETF空头)
A1: 证券公司净资本计算表
G2: 单位： | H2: 亿元
A3: 项目 | C3: 行次 | D3: 期初余额 | E3: 期末余额 | F3: 扣减比例 | G3: 应计算的金额
G4: 期初余额 | H4: 期末余额
A5: 净资产 | C5: 1 | D5: 164.9602 | G5: =D5 -> 164.9602
B6: 减： 优先股及永续次级债等 | C6: 2
B7: 减： 资产项目的风险调整合计 | C7: 3 | F7: 1
B8: 存出保证金 | C8: 4 | D8: =SUM(D9:D11) -> 0 | E8: =SUM(E9:E11) -> 0 | H8: =SUM(H9:H11) -> 0
B9: 其中：履约保证金 | C9: 5 | F9: 0.1
B10: 期货（ 期权） 保证金 | C10: 6 | E10: ='1.1NSFR(不含ETF空头)'!$D$18 -> 0 | F10: 1 | H10: =E10*F10 -> 0
B11: 其他存出保证金 | C11: 7
B12: 长期股权投资 | C12: 8 | F12: 1
B13: 投资性房地产、 固定资产、 在建工程 | C13: 9 | F13: 1
B14: 其他 | C14: 10 | F14: 1
B15: 减： 或有负债的风险调整合计 | C15: 11
B16: 对外担保金额及担保承诺 | C16: 12 | F16: 1
B17: 其他或有负债 | C17: 13 | F17: 1
B18: 加： 中国证监会认定或核准的其他调整项目合计 | C18: 14
B19: 母公司提供的担保承诺 | C19: 15 | F19: 1
B20: 其他项目 | C20: 16
B21: 减： 中国证监会认定或核准的其他调整项目合计 | C21: 17
B22: 所有权受限等无法变现的资产(如被冻结） | C22: 18 | F22: 1
B23: 其他项目 | C23: 19
A24: 核心净资本 | C24: 20 | D24: =D5-D6-D7-D8-D12-D13-D14-D15-D16-D17-D18-D19-D20-D21-D22-D23 -> 164.9602 | G24: =G5-G6-G7-G8-G12-G13-G14-G15-G16-G17-G18-G19-G20-G21-G22-G23 -> 164.9602 | H24: =G24+H5-H6-H7-H8-H12-H13-H14-H15-H16-H17-H18-H19-H20-H21-H22-H23 -> 164.9602
B25: 加： 附属净资本 | C25: 21
B26: 借入的次级债（ 含永续次级债） | C26: 22
B27: 中国证监会认定或核准的其他调整项目 | C27: 23
A28: 净资本 | C28: 24 | D28: =SUM(D24:D25) -> 164.9602 | G28: =SUM(G24:G25) -> 164.9602 | H28: =SUM(H24:H25) -> 164.9602 | J28: 160以上保证
G29: ↓ | H29: =H28/G28-1 -> 0
B31: 净资本/风险资本准备影响 | G31: =$G$28/'1.3风险资本准备计算表(不含ETF空头)'!$G$102 -> 1.7833535 | H31: =$H$28/'1.3风险资本准备计算表(不含ETF空头)'!$H$102 -> 1.6760841
G32: ↓ | H32: =H31/G31-1 -> -0.060150376

Sheet 1.3风险资本准备计算表(不含ETF空头)
A1: 证券公司风险资本准备计算表
G2: 单位： | H2: 亿元
A3: 项目 | C3: 行次 | D3: 期初余额 | E3: 期末余额 | F3: 计算标准 | G3: 风险资本准备
G4: 期初余额 | H4: 期末余额
A5: 1. 市场风险资本准备 | C5: 1 | H5: =SUM(H6,H18,H46,H49) -> 7.4
A6: 其中：（ 1） 权益类证券及其衍生品规模 | C6: 2 | H6: =SUM(H7:H17) -> 0.4
B7: 上海 180 指数、 深圳 100指数、 沪深 300 指数成分股 | C7: 3 | F7: 0.1 | H7: =E7*F7 -> 0
B8: 一般上市股票 | C8: 4 | F8: 0.3 | H8: =E8*F8 -> 0
B9: 流通受限的股票 | C9: 5 | F9: 0.5 | H9: =E9*F9 -> 0
B10: 其他股票 | C10: 6 | F10: 0.8 | H10: =E10*F10 -> 0
B11: 权益类基金 | C11: 7
B12: 其中： 指数基金 | C12: 8 | F12: 0.05 | H12: =E12*F12 -> 0
B13: 分级基金中的非优先级基金 | C13: 9 | F13: 0.5 | H13: =E13*F13 -> 0
B14: 其他权益类基金 | C14: 10 | F14: 0.1 | H14: =E14*F14 -> 0
B15: 股指期货、 权益互换及卖出期权 | C15: 11 | E15: =汇总情况!$D$4*10% -> 2 | F15: 0.2 | H15: =E15*F15 -> 0.4 | I15: 互换合约端
B16: 买入期权 | C16: 12 | F16: 1 | H16: =E16*F16 -> 0
B17: 其他 | C17: 13
A18: （ 2） 非权益类证券及其衍生品规模 | C18: 14 | H18: =SUM(H19:H45) -> 7
B19: 国债、 中央银行票据、 国开债 | C19: 15 | F19: 0 | H19: =E19*F19 -> 0
B20: 政策性金融债、 政府支持机构债券 | C20: 16 | F20: 0.01 | H20: =E20*F20 -> 0
B21: 地方政府债券 | C21: 17 | F21: 0.05 | H21: =E21*F21 -> 0
B22: 同业存单 | C22: 18 | F22: 0.05 | H22: =E22*F22 -> 0
B23: 信用评级 AAA 级的信用债券 | C23: 19 | F23: 0.1 | H23: =E23*F23 -> 0
B24: 信用评级 AAA 级以下， AA级（ 含） 以上的信用债券 | C24: 20 | F24: 0.15 | H24: =E24*F24 -> 0
B25: 信用评级 AA 级以下， BBB级（ 含） 以上的信用债券 | C25: 21 | F25: 0.5 | H25: =E25*F25 -> 0
B26: 信用评级 BBB 级以下的信用债券 | C26: 22 | F26: 0.8 | H26: =E26*F26 -> 0
B27: 非权益类基金 | C27: 23
B28: 其中：货币基金 | C28: 24 | F28: 0.05 | H28: =E28*F28 -> 0
B29: 利率债指数基金 | C29: 25 | F29: 0.06 | H29: =E29*F29 -> 0
B30: 其他非权益类基金 | C30: 26 | F30: 0.1 | H30: =E30*F30 -> 0
B31: 国债期货、 债券远期及利率互换 | C31: 27 | F31: 0.2 | H31: =E31*F31 -> 0
B32: 外汇衍生品 | C32: 28 | F32: 0.2 | H32: =E32*F32 -> 0
B33: 集合及信托等产品 | C33: 29
B34: 其中： 未约定先行承担亏损 | C34: 30 | F34: 0.25 | H34: =E34*F34 -> 0
B35: 约定先行承担亏损 | C35: 31 | F35: 0.5 | H35: =E35*F35 -> 0
B36: 单一产品 | C36: 32 | E36: =汇总情况!$D$7 -> 14 | F36: 0.5 | H36: =E36*F36 -> 7 | I36: 按照产品规模填列
B37: 大宗商品现货（ 含黄金） | C37: 33 | F37: 0.08 | H37: =E37*F37 -> 0
B38: 大宗商品衍生品（ 不含期权） | C38: 34 | F38: 0.2 | H38: =E38*F38 -> 0
B39: 非权益类期权 | C39: 35
B40: 其中：买入期权 | C40: 36 | F40: 1 | H40: =E40*F40 -> 0
...

Sheet 1.4LCR(不含ETF空头)
A1: 证券公司流动性覆盖率计算表
E2: 单位： | F2: 亿元
A3: 项目 | C3: 行次 | D3: 期末金额 | E3: 折算率 | F3: 折算后金额 | G3: 原始值
A4: 优质流动性资产 | C4: 1 | D4: =SUM(F5:F21)+G4 -> 109.81 | G4: 118.81
A5: 其中： | B5: 货币资金 | C5: 2 | D5: ='1.1NSFR(不含ETF空头)'!$D$15 -> -9 | E5: 1 | F5: =D5*E5 -> -9
B6: 结算备付金 | C6: 3 | E6: 1 | F6: =D6*E6 -> 0
B7: 国债、中央银行票据、国开债 | C7: 4 | E7: 1 | F7: =D7*E7 -> 0
B8: 减：已冻结或质押部分 | C8: 5 | E8: 1 | F8: =-D8*E8 -> 0
B9: 政策性金融债、政府支持机构债券 | C9: 6 | E9: 0.99 | F9: =D9*E9 -> 0
B10: 减：已冻结或质押部分 | C10: 7 | E10: 0.99 | F10: =-D10*E10 -> 0
B11: 地方政府债券 | C11: 8 | E11: 0.95 | F11: =D11*E11 -> 0
B12: 减：已冻结或质押部分 | C12: 9 | E12: 0.95 | F12: =-D12*E12 -> 0
B13: 同业存单 | C13: 10 | E13: 0.95 | F13: =D13*E13 -> 0
B14: 减：已冻结或质押部分 | C14: 11 | E14: 0.95 | F14: =-D14*E14 -> 0
B15: 信用评级 AAA 级的信用债券 | C15: 12 | E15: 0.96 | F15: =D15*E15 -> 0
B16: 减：已冻结或质押部分 | C16: 13 | E16: 0.96 | F16: =-D16*E16 -> 0
B17: 信用评级 AAA 级以下，AA+级(不含）以上的信用债券 | C17: 14 | E17: 0.9 | F17: =D17*E17 -> 0
B18: 减：已冻结或质押部分 | C18: 15 | E18: 0.9 | F18: =-D18*E18 -> 0
B19: 货币基金 | C19: 16 | E19: 0.9 | F19: =D19*E19 -> 0
B20: 上海 180 指数、深圳 100 指数、沪深 300指数成分股及宽基指数类 ETF | C20: 17 | E20: 0.4 | F20: =D20*E20 -> 0
B21: 减：已冻结或质押部分 | C21: 18 | E21: 0.4 | F21: =-D21*E21 -> 0
A22: 未来 30 日现金流出 | C22: 19 | D22: =SUM(F24:F38,F40:F41,F43:F49,F51:F54,F56,F58:F59) -> 4.04
A23: 1.30 日内到期的负债现金流出 | C23: 20
B24: 短期借款 | C24: 21 | E24: 1 | F24: =D24*E24 -> 0
B25: 拆入资金 | C25: 22 | E25: 1 | F25: =D25*E25 -> 0
B26: 卖出回购（按质押物分类） | C26: 23
B27: 其中：国债、中央银行票据、国开债 | C27: 24 | E27: 0 | F27: =D27*E27 -> 0
B28: 政策性金融债、政府支持机构债券 | C28: 25 | E28: 0.01 | F28: =D28*E28 -> 0
B29: 地方政府债券 | C29: 26 | E29: 0.05 | F29: =D29*E29 -> 0
B30: 同业存单 | C30: 27 | E30: 0.05 | F30: =D30*E30 -> 0
B31: 信用评级 AAA 级的信用债券 | C31: 28 | E31: 0.04 | F31: =D31*E31 -> 0
B32: 信用评级 AAA 级以下，AA+级(不含）以上的信用债券 | C32: 29 | E32: 0.1 | F32: =D32*E32 -> 0
B33: 信用评级 AA 级的信用债券 | C33: 30 | E33: 0.3 | F33: =D33*E33 -> 0
B34: 债券基金 | C34: 31 | E34: 0.1 | F34: =D34*E34 -> 0
B35: 其他 | C35: 32 | E35: 1 | F35: =D35*E35 -> 0
B36: 应付职工薪酬、税费、利息和股利 | C36: 33 | E36: 1 | F36: =D36*E36 -> 0
B37: 交易性金融负债、衍生金融负债 | C37: 34 | D37: =汇总情况!$D$4*20% -> 4 | E37: 1 | F37: =D37*E37 -> 4 | G37: 算全额，浮动盈亏假设客户浮盈20%吧
B38: 30 日内须偿还的次级债务和其他债务 | C38: 35 | E38: 1 | F38: =D38*E38 -> 0
A39: 2.或有负债 | C39: 36
B40: 对外担保金额及担保承诺 | C40: 37 | E40: 0.03 | F40: =D40*E40 -> 0
...
